package tja.machines.multiblocks;

import codechicken.lib.render.CCRenderState;
import codechicken.lib.render.pipeline.IVertexOperation;
import codechicken.lib.vec.Matrix4;
import gregtech.api.metatileentity.MetaTileEntity;
import gregtech.api.metatileentity.interfaces.IGregTechTileEntity;
import gregtech.api.metatileentity.multiblock.IMultiblockPart;
import gregtech.api.metatileentity.multiblock.MultiblockAbility;
import gregtech.api.metatileentity.multiblock.MultiblockWithDisplayBase;
import gregtech.api.pattern.BlockPattern;
import gregtech.api.pattern.FactoryBlockPattern;
import gregtech.api.pattern.PatternMatchContext;
import gregtech.client.renderer.ICubeRenderer;
import gregtech.client.renderer.texture.Textures;
import gregtech.common.metatileentities.multi.BoilerType;
import net.minecraft.util.ResourceLocation;
import net.minecraftforge.fml.relauncher.Side;
import net.minecraftforge.fml.relauncher.SideOnly;
import tja.capability.handler.IBoilerHandler;
import tja.capability.workables.MegaBoilerRecipeLogic;

import javax.annotation.Nonnull;

public class MetaTileEntityMegaBoiler extends MultiblockWithDisplayBase implements IBoilerHandler {

    private final MegaBoilerRecipeLogic recipeLogic = new MegaBoilerRecipeLogic(this);
    private final BoilerType boilerType;

    public MetaTileEntityMegaBoiler(ResourceLocation metaTileEntityId, BoilerType boilerType) {
        super(metaTileEntityId);
        this.boilerType = boilerType;
        this.reinitializeStructurePattern();
    }

    @Override
    public MetaTileEntity createMetaTileEntity(IGregTechTileEntity iGregTechTileEntity) {
        return new MetaTileEntityMegaBoiler(this.metaTileEntityId, this.boilerType);
    }

    @Override
    protected void updateFormedValid() {
        if (this.getOffsetTimer() > 40 && ((this.getMaintenanceProblems() >> 5) & 1) != 0)
            this.recipeLogic.update();
    }

    @Nonnull
    @Override
    protected BlockPattern createStructurePattern() {
        return this.boilerType == null ? FactoryBlockPattern.start().build() : FactoryBlockPattern.start()
                .aisle("FFFFFFFFFFFFFFF", "CCCCCCCCCCCCCCC", "CCCCCCCCCCCCCCC", "CCCCCCCCCCCCCCC", "CCCCCCCCCCCCCCC", "CCCCCCCCCCCCCCC", "CCCCCCCCCCCCCCC", "CCCCCCCCCCCCCCC", "CCCCCCCCCCCCCCC", "CCCCCCCCCCCCCCC", "CCCCCCCCCCCCCCC", "CCCCCCCCCCCCCCC", "CCCCCCCCCCCCCCC", "CCCCCCCCCCCCCCC", "CCCCCCCCCCCCCCC", "CCCCCCCCCCCCCCC", "CCCCCCCCCCCCCCC", "CCCCCCCCCCCCCCC", "CCCCCCCCCCCCCCC", "CCCCCCCCCCCCCCC")
                .aisle("FFFFFFFFFFFFFFF", "CPPPPPPPPPPPPPC", "CPPPPPPPPPPPPPC", "CPPPPPPPPPPPPPC", "CPPPPPPPPPPPPPC", "CPPPPPPPPPPPPPC", "CPPPPPPPPPPPPPC", "CPPPPPPPPPPPPPC", "CPPPPPPPPPPPPPC", "CPPPPPPPPPPPPPC", "CPPPPPPPPPPPPPC", "CPPPPPPPPPPPPPC", "CPPPPPPPPPPPPPC", "CPPPPPPPPPPPPPC", "CPPPPPPPPPPPPPC", "CPPPPPPPPPPPPPC", "CPPPPPPPPPPPPPC", "CPPPPPPPPPPPPPC", "CPPPPPPPPPPPPPC", "CCCCCCCCCCCCCCC")
                .aisle("FFFFFFFFFFFFFFF", "CPPPPPPPPPPPPPC", "CPPPPPPPPPPPPPC", "CPPPPPPPPPPPPPC", "CPPPPPPPPPPPPPC", "CPPPPPPPPPPPPPC", "CPPPPPPPPPPPPPC", "CPPPPPPPPPPPPPC", "CPPPPPPPPPPPPPC", "CPPPPPPPPPPPPPC", "CPPPPPPPPPPPPPC", "CPPPPPPPPPPPPPC", "CPPPPPPPPPPPPPC", "CPPPPPPPPPPPPPC", "CPPPPPPPPPPPPPC", "CPPPPPPPPPPPPPC", "CPPPPPPPPPPPPPC", "CPPPPPPPPPPPPPC", "CPPPPPPPPPPPPPC", "CCCCCCCCCCCCCCC")
                .aisle("FFFFFFFFFFFFFFF", "CPPPPPPPPPPPPPC", "CPPPPPPPPPPPPPC", "CPPPPPPPPPPPPPC", "CPPPPPPPPPPPPPC", "CPPPPPPPPPPPPPC", "CPPPPPPPPPPPPPC", "CPPPPPPPPPPPPPC", "CPPPPPPPPPPPPPC", "CPPPPPPPPPPPPPC", "CPPPPPPPPPPPPPC", "CPPPPPPPPPPPPPC", "CPPPPPPPPPPPPPC", "CPPPPPPPPPPPPPC", "CPPPPPPPPPPPPPC", "CPPPPPPPPPPPPPC", "CPPPPPPPPPPPPPC", "CPPPPPPPPPPPPPC", "CPPPPPPPPPPPPPC", "CCCCCCCCCCCCCCC")
                .aisle("FFFFFFFFFFFFFFF", "CPPPPPPPPPPPPPC", "CPPPPPPPPPPPPPC", "CPPPPPPPPPPPPPC", "CPPPPPPPPPPPPPC", "CPPPPPPPPPPPPPC", "CPPPPPPPPPPPPPC", "CPPPPPPPPPPPPPC", "CPPPPPPPPPPPPPC", "CPPPPPPPPPPPPPC", "CPPPPPPPPPPPPPC", "CPPPPPPPPPPPPPC", "CPPPPPPPPPPPPPC", "CPPPPPPPPPPPPPC", "CPPPPPPPPPPPPPC", "CPPPPPPPPPPPPPC", "CPPPPPPPPPPPPPC", "CPPPPPPPPPPPPPC", "CPPPPPPPPPPPPPC", "CCCCCCCCCCCCCCC")
                .aisle("FFFFFFFFFFFFFFF", "CPPPPPPPPPPPPPC", "CPPPPPPPPPPPPPC", "CPPPPPPPPPPPPPC", "CPPPPPPPPPPPPPC", "CPPPPPPPPPPPPPC", "CPPPPPPPPPPPPPC", "CPPPPPPPPPPPPPC", "CPPPPPPPPPPPPPC", "CPPPPPPPPPPPPPC", "CPPPPPPPPPPPPPC", "CPPPPPPPPPPPPPC", "CPPPPPPPPPPPPPC", "CPPPPPPPPPPPPPC", "CPPPPPPPPPPPPPC", "CPPPPPPPPPPPPPC", "CPPPPPPPPPPPPPC", "CPPPPPPPPPPPPPC", "CPPPPPPPPPPPPPC", "CCCCCCCCCCCCCCC")
                .aisle("FFFFFFFFFFFFFFF", "CPPPPPPPPPPPPPC", "CPPPPPPPPPPPPPC", "CPPPPPPPPPPPPPC", "CPPPPPPPPPPPPPC", "CPPPPPPPPPPPPPC", "CPPPPPPPPPPPPPC", "CPPPPPPPPPPPPPC", "CPPPPPPPPPPPPPC", "CPPPPPPPPPPPPPC", "CPPPPPPPPPPPPPC", "CPPPPPPPPPPPPPC", "CPPPPPPPPPPPPPC", "CPPPPPPPPPPPPPC", "CPPPPPPPPPPPPPC", "CPPPPPPPPPPPPPC", "CPPPPPPPPPPPPPC", "CPPPPPPPPPPPPPC", "CPPPPPPPPPPPPPC", "CCCCCCCCCCCCCCC")
                .aisle("FFFFFFFFFFFFFFF", "CPPPPPPPPPPPPPC", "CPPPPPPPPPPPPPC", "CPPPPPPPPPPPPPC", "CPPPPPPPPPPPPPC", "CPPPPPPPPPPPPPC", "CPPPPPPPPPPPPPC", "CPPPPPPPPPPPPPC", "CPPPPPPPPPPPPPC", "CPPPPPPPPPPPPPC", "CPPPPPPPPPPPPPC", "CPPPPPPPPPPPPPC", "CPPPPPPPPPPPPPC", "CPPPPPPPPPPPPPC", "CPPPPPPPPPPPPPC", "CPPPPPPPPPPPPPC", "CPPPPPPPPPPPPPC", "CPPPPPPPPPPPPPC", "CPPPPPPPPPPPPPC", "CCCCCCCCCCCCCCC")
                .aisle("FFFFFFFFFFFFFFF", "CPPPPPPPPPPPPPC", "CPPPPPPPPPPPPPC", "CPPPPPPPPPPPPPC", "CPPPPPPPPPPPPPC", "CPPPPPPPPPPPPPC", "CPPPPPPPPPPPPPC", "CPPPPPPPPPPPPPC", "CPPPPPPPPPPPPPC", "CPPPPPPPPPPPPPC", "CPPPPPPPPPPPPPC", "CPPPPPPPPPPPPPC", "CPPPPPPPPPPPPPC", "CPPPPPPPPPPPPPC", "CPPPPPPPPPPPPPC", "CPPPPPPPPPPPPPC", "CPPPPPPPPPPPPPC", "CPPPPPPPPPPPPPC", "CPPPPPPPPPPPPPC", "CCCCCCCCCCCCCCC")
                .aisle("FFFFFFFFFFFFFFF", "CPPPPPPPPPPPPPC", "CPPPPPPPPPPPPPC", "CPPPPPPPPPPPPPC", "CPPPPPPPPPPPPPC", "CPPPPPPPPPPPPPC", "CPPPPPPPPPPPPPC", "CPPPPPPPPPPPPPC", "CPPPPPPPPPPPPPC", "CPPPPPPPPPPPPPC", "CPPPPPPPPPPPPPC", "CPPPPPPPPPPPPPC", "CPPPPPPPPPPPPPC", "CPPPPPPPPPPPPPC", "CPPPPPPPPPPPPPC", "CPPPPPPPPPPPPPC", "CPPPPPPPPPPPPPC", "CPPPPPPPPPPPPPC", "CPPPPPPPPPPPPPC", "CCCCCCCCCCCCCCC")
                .aisle("FFFFFFFFFFFFFFF", "CPPPPPPPPPPPPPC", "CPPPPPPPPPPPPPC", "CPPPPPPPPPPPPPC", "CPPPPPPPPPPPPPC", "CPPPPPPPPPPPPPC", "CPPPPPPPPPPPPPC", "CPPPPPPPPPPPPPC", "CPPPPPPPPPPPPPC", "CPPPPPPPPPPPPPC", "CPPPPPPPPPPPPPC", "CPPPPPPPPPPPPPC", "CPPPPPPPPPPPPPC", "CPPPPPPPPPPPPPC", "CPPPPPPPPPPPPPC", "CPPPPPPPPPPPPPC", "CPPPPPPPPPPPPPC", "CPPPPPPPPPPPPPC", "CPPPPPPPPPPPPPC", "CCCCCCCCCCCCCCC")
                .aisle("FFFFFFFFFFFFFFF", "CPPPPPPPPPPPPPC", "CPPPPPPPPPPPPPC", "CPPPPPPPPPPPPPC", "CPPPPPPPPPPPPPC", "CPPPPPPPPPPPPPC", "CPPPPPPPPPPPPPC", "CPPPPPPPPPPPPPC", "CPPPPPPPPPPPPPC", "CPPPPPPPPPPPPPC", "CPPPPPPPPPPPPPC", "CPPPPPPPPPPPPPC", "CPPPPPPPPPPPPPC", "CPPPPPPPPPPPPPC", "CPPPPPPPPPPPPPC", "CPPPPPPPPPPPPPC", "CPPPPPPPPPPPPPC", "CPPPPPPPPPPPPPC", "CPPPPPPPPPPPPPC", "CCCCCCCCCCCCCCC")
                .aisle("FFFFFFFFFFFFFFF", "CPPPPPPPPPPPPPC", "CPPPPPPPPPPPPPC", "CPPPPPPPPPPPPPC", "CPPPPPPPPPPPPPC", "CPPPPPPPPPPPPPC", "CPPPPPPPPPPPPPC", "CPPPPPPPPPPPPPC", "CPPPPPPPPPPPPPC", "CPPPPPPPPPPPPPC", "CPPPPPPPPPPPPPC", "CPPPPPPPPPPPPPC", "CPPPPPPPPPPPPPC", "CPPPPPPPPPPPPPC", "CPPPPPPPPPPPPPC", "CPPPPPPPPPPPPPC", "CPPPPPPPPPPPPPC", "CPPPPPPPPPPPPPC", "CPPPPPPPPPPPPPC", "CCCCCCCCCCCCCCC")
                .aisle("FFFFFFFFFFFFFFF", "CPPPPPPPPPPPPPC", "CPPPPPPPPPPPPPC", "CPPPPPPPPPPPPPC", "CPPPPPPPPPPPPPC", "CPPPPPPPPPPPPPC", "CPPPPPPPPPPPPPC", "CPPPPPPPPPPPPPC", "CPPPPPPPPPPPPPC", "CPPPPPPPPPPPPPC", "CPPPPPPPPPPPPPC", "CPPPPPPPPPPPPPC", "CPPPPPPPPPPPPPC", "CPPPPPPPPPPPPPC", "CPPPPPPPPPPPPPC", "CPPPPPPPPPPPPPC", "CPPPPPPPPPPPPPC", "CPPPPPPPPPPPPPC", "CPPPPPPPPPPPPPC", "CCCCCCCCCCCCCCC")
                .aisle("FFFFFFFFFFFFFFF", "CCCCCCCCCCCCCCC", "CCCCCCCSCCCCCCC", "CCCCCCCCCCCCCCC", "CCCCCCCCCCCCCCC", "CCCCCCCCCCCCCCC", "CCCCCCCCCCCCCCC", "CCCCCCCCCCCCCCC", "CCCCCCCCCCCCCCC", "CCCCCCCCCCCCCCC", "CCCCCCCCCCCCCCC", "CCCCCCCCCCCCCCC", "CCCCCCCCCCCCCCC", "CCCCCCCCCCCCCCC", "CCCCCCCCCCCCCCC", "CCCCCCCCCCCCCCC", "CCCCCCCCCCCCCCC", "CCCCCCCCCCCCCCC", "CCCCCCCCCCCCCCC", "CCCCCCCCCCCCCCC")
                .where('S', this.selfPredicate())
                .where('C', states(this.boilerType.casingState).setMinGlobalLimited(200)
                        .or(abilities(MultiblockAbility.EXPORT_FLUIDS)))
                .where('F', states(this.boilerType.fireboxState).setMinGlobalLimited(200)
                        .or(abilities(MultiblockAbility.IMPORT_ITEMS, MultiblockAbility.IMPORT_FLUIDS, MultiblockAbility.MAINTENANCE_HATCH,
                                MultiblockAbility.EXPORT_ITEMS))
                        .or(abilities(MultiblockAbility.MUFFLER_HATCH).setExactLimit(1)))
                .where('P', states(this.boilerType.pipeState))
                .build();
    }

    @Override
    protected void formStructure(PatternMatchContext context) {
        super.formStructure(context);
        this.recipeLogic.initialize(this.getAbilities(MultiblockAbility.IMPORT_ITEMS).size());
    }

    @Override
    public void invalidateStructure() {
        super.invalidateStructure();
        this.recipeLogic.invalidate();
    }

    @Override
    @SideOnly(Side.CLIENT)
    public void renderMetaTileEntity(CCRenderState renderState, Matrix4 translation, IVertexOperation[] pipeline) {
        super.renderMetaTileEntity(renderState, translation, pipeline);
        Textures.MULTIBLOCK_WORKABLE_OVERLAY.renderOrientedState(renderState, translation, pipeline, this.frontFacing, this.recipeLogic.isActive(), this.recipeLogic.isWorkingEnabled());
    }

    @Override
    @SideOnly(Side.CLIENT)
    public ICubeRenderer getBaseTexture(IMultiblockPart iMultiblockPart) {
        return this.boilerType.casingRenderer;
    }

    @Override
    public double getHeatEfficiencyMultiplier() {
        final int efficiency = this.boilerType == BoilerType.TUNGSTENSTEEL ? 32 : this.boilerType == BoilerType.TITANIUM ? 31 : this.boilerType == BoilerType.STEEL ? 30 : 28;
        final double temperature = this.recipeLogic.heat() / (this.getMaxTemperature() * 1.0);
        return 1.0 + Math.round(efficiency * temperature) / 100.0;
    }

    @Override
    public double getFuelConsumptionMultiplier() {
        return this.boilerType == BoilerType.TUNGSTENSTEEL ? 5.4 : this.boilerType == BoilerType.TITANIUM ? 3.0 : this.boilerType == BoilerType.STEEL ? 1.6 : 1.0;
    }

    @Override
    public int getBaseSteamOutput() {
        return this.boilerType.steamPerTick();
    }

    @Override
    public int getMaxTemperature() {
        return this.boilerType == BoilerType.TUNGSTENSTEEL ? 7800 : this.boilerType == BoilerType.TITANIUM ? 3700 : this.boilerType == BoilerType.STEEL ? 1600 : 900;
    }
}
