package tja.machines.multiblocks;

import gregtech.api.metatileentity.MetaTileEntity;
import gregtech.api.metatileentity.interfaces.IGregTechTileEntity;
import gregtech.api.metatileentity.multiblock.IMultiblockPart;
import gregtech.api.metatileentity.multiblock.MultiblockAbility;
import gregtech.api.metatileentity.multiblock.MultiblockWithDisplayBase;
import gregtech.api.pattern.BlockPattern;
import gregtech.api.pattern.FactoryBlockPattern;
import gregtech.client.renderer.ICubeRenderer;
import gregtech.common.metatileentities.multi.BoilerType;
import net.minecraft.util.ResourceLocation;
import net.minecraftforge.fml.relauncher.Side;
import net.minecraftforge.fml.relauncher.SideOnly;

import javax.annotation.Nonnull;

public class MetaTileEntityMegaBoiler extends MultiblockWithDisplayBase {

    private final BoilerType boilerType;

    public MetaTileEntityMegaBoiler(ResourceLocation metaTileEntityId, BoilerType boilerType) {
        super(metaTileEntityId);
        this.boilerType = boilerType;
        this.reinitializeStructurePattern();
    }

    @Override
    public MetaTileEntity createMetaTileEntity(IGregTechTileEntity iGregTechTileEntity) {
        return new MetaTileEntityMegaBoiler(this.metaTileEntityId, this.boilerType);
    }

    @Override
    protected void updateFormedValid() {

    }

    @Nonnull
    @Override
    protected BlockPattern createStructurePattern() {
        return this.boilerType == null ? FactoryBlockPattern.start().build() : FactoryBlockPattern.start()
                .aisle("FFFFFFFFFFFFFFF", "CCCCCCCCCCCCCCC", "CCCCCCCCCCCCCCC", "CCCCCCCCCCCCCCC", "CCCCCCCCCCCCCCC", "CCCCCCCCCCCCCCC", "CCCCCCCCCCCCCCC", "CCCCCCCCCCCCCCC", "CCCCCCCCCCCCCCC", "CCCCCCCCCCCCCCC", "CCCCCCCCCCCCCCC", "CCCCCCCCCCCCCCC", "CCCCCCCCCCCCCCC", "CCCCCCCCCCCCCCC", "CCCCCCCCCCCCCCC", "CCCCCCCCCCCCCCC", "CCCCCCCCCCCCCCC", "CCCCCCCCCCCCCCC", "CCCCCCCCCCCCCCC", "CCCCCCCCCCCCCCC")
                .aisle("FFFFFFFFFFFFFFF", "CPPPPPPPPPPPPPC", "CPPPPPPPPPPPPPC", "CPPPPPPPPPPPPPC", "CPPPPPPPPPPPPPC", "CPPPPPPPPPPPPPC", "CPPPPPPPPPPPPPC", "CPPPPPPPPPPPPPC", "CPPPPPPPPPPPPPC", "CPPPPPPPPPPPPPC", "CPPPPPPPPPPPPPC", "CPPPPPPPPPPPPPC", "CPPPPPPPPPPPPPC", "CPPPPPPPPPPPPPC", "CPPPPPPPPPPPPPC", "CPPPPPPPPPPPPPC", "CPPPPPPPPPPPPPC", "CPPPPPPPPPPPPPC", "CPPPPPPPPPPPPPC", "CCCCCCCCCCCCCCC")
                .aisle("FFFFFFFFFFFFFFF", "CPPPPPPPPPPPPPC", "CPPPPPPPPPPPPPC", "CPPPPPPPPPPPPPC", "CPPPPPPPPPPPPPC", "CPPPPPPPPPPPPPC", "CPPPPPPPPPPPPPC", "CPPPPPPPPPPPPPC", "CPPPPPPPPPPPPPC", "CPPPPPPPPPPPPPC", "CPPPPPPPPPPPPPC", "CPPPPPPPPPPPPPC", "CPPPPPPPPPPPPPC", "CPPPPPPPPPPPPPC", "CPPPPPPPPPPPPPC", "CPPPPPPPPPPPPPC", "CPPPPPPPPPPPPPC", "CPPPPPPPPPPPPPC", "CPPPPPPPPPPPPPC", "CCCCCCCCCCCCCCC")
                .aisle("FFFFFFFFFFFFFFF", "CPPPPPPPPPPPPPC", "CPPPPPPPPPPPPPC", "CPPPPPPPPPPPPPC", "CPPPPPPPPPPPPPC", "CPPPPPPPPPPPPPC", "CPPPPPPPPPPPPPC", "CPPPPPPPPPPPPPC", "CPPPPPPPPPPPPPC", "CPPPPPPPPPPPPPC", "CPPPPPPPPPPPPPC", "CPPPPPPPPPPPPPC", "CPPPPPPPPPPPPPC", "CPPPPPPPPPPPPPC", "CPPPPPPPPPPPPPC", "CPPPPPPPPPPPPPC", "CPPPPPPPPPPPPPC", "CPPPPPPPPPPPPPC", "CPPPPPPPPPPPPPC", "CCCCCCCCCCCCCCC")
                .aisle("FFFFFFFFFFFFFFF", "CPPPPPPPPPPPPPC", "CPPPPPPPPPPPPPC", "CPPPPPPPPPPPPPC", "CPPPPPPPPPPPPPC", "CPPPPPPPPPPPPPC", "CPPPPPPPPPPPPPC", "CPPPPPPPPPPPPPC", "CPPPPPPPPPPPPPC", "CPPPPPPPPPPPPPC", "CPPPPPPPPPPPPPC", "CPPPPPPPPPPPPPC", "CPPPPPPPPPPPPPC", "CPPPPPPPPPPPPPC", "CPPPPPPPPPPPPPC", "CPPPPPPPPPPPPPC", "CPPPPPPPPPPPPPC", "CPPPPPPPPPPPPPC", "CPPPPPPPPPPPPPC", "CCCCCCCCCCCCCCC")
                .aisle("FFFFFFFFFFFFFFF", "CPPPPPPPPPPPPPC", "CPPPPPPPPPPPPPC", "CPPPPPPPPPPPPPC", "CPPPPPPPPPPPPPC", "CPPPPPPPPPPPPPC", "CPPPPPPPPPPPPPC", "CPPPPPPPPPPPPPC", "CPPPPPPPPPPPPPC", "CPPPPPPPPPPPPPC", "CPPPPPPPPPPPPPC", "CPPPPPPPPPPPPPC", "CPPPPPPPPPPPPPC", "CPPPPPPPPPPPPPC", "CPPPPPPPPPPPPPC", "CPPPPPPPPPPPPPC", "CPPPPPPPPPPPPPC", "CPPPPPPPPPPPPPC", "CPPPPPPPPPPPPPC", "CCCCCCCCCCCCCCC")
                .aisle("FFFFFFFFFFFFFFF", "CPPPPPPPPPPPPPC", "CPPPPPPPPPPPPPC", "CPPPPPPPPPPPPPC", "CPPPPPPPPPPPPPC", "CPPPPPPPPPPPPPC", "CPPPPPPPPPPPPPC", "CPPPPPPPPPPPPPC", "CPPPPPPPPPPPPPC", "CPPPPPPPPPPPPPC", "CPPPPPPPPPPPPPC", "CPPPPPPPPPPPPPC", "CPPPPPPPPPPPPPC", "CPPPPPPPPPPPPPC", "CPPPPPPPPPPPPPC", "CPPPPPPPPPPPPPC", "CPPPPPPPPPPPPPC", "CPPPPPPPPPPPPPC", "CPPPPPPPPPPPPPC", "CCCCCCCCCCCCCCC")
                .aisle("FFFFFFFFFFFFFFF", "CPPPPPPPPPPPPPC", "CPPPPPPPPPPPPPC", "CPPPPPPPPPPPPPC", "CPPPPPPPPPPPPPC", "CPPPPPPPPPPPPPC", "CPPPPPPPPPPPPPC", "CPPPPPPPPPPPPPC", "CPPPPPPPPPPPPPC", "CPPPPPPPPPPPPPC", "CPPPPPPPPPPPPPC", "CPPPPPPPPPPPPPC", "CPPPPPPPPPPPPPC", "CPPPPPPPPPPPPPC", "CPPPPPPPPPPPPPC", "CPPPPPPPPPPPPPC", "CPPPPPPPPPPPPPC", "CPPPPPPPPPPPPPC", "CPPPPPPPPPPPPPC", "CCCCCCCCCCCCCCC")
                .aisle("FFFFFFFFFFFFFFF", "CPPPPPPPPPPPPPC", "CPPPPPPPPPPPPPC", "CPPPPPPPPPPPPPC", "CPPPPPPPPPPPPPC", "CPPPPPPPPPPPPPC", "CPPPPPPPPPPPPPC", "CPPPPPPPPPPPPPC", "CPPPPPPPPPPPPPC", "CPPPPPPPPPPPPPC", "CPPPPPPPPPPPPPC", "CPPPPPPPPPPPPPC", "CPPPPPPPPPPPPPC", "CPPPPPPPPPPPPPC", "CPPPPPPPPPPPPPC", "CPPPPPPPPPPPPPC", "CPPPPPPPPPPPPPC", "CPPPPPPPPPPPPPC", "CPPPPPPPPPPPPPC", "CCCCCCCCCCCCCCC")
                .aisle("FFFFFFFFFFFFFFF", "CPPPPPPPPPPPPPC", "CPPPPPPPPPPPPPC", "CPPPPPPPPPPPPPC", "CPPPPPPPPPPPPPC", "CPPPPPPPPPPPPPC", "CPPPPPPPPPPPPPC", "CPPPPPPPPPPPPPC", "CPPPPPPPPPPPPPC", "CPPPPPPPPPPPPPC", "CPPPPPPPPPPPPPC", "CPPPPPPPPPPPPPC", "CPPPPPPPPPPPPPC", "CPPPPPPPPPPPPPC", "CPPPPPPPPPPPPPC", "CPPPPPPPPPPPPPC", "CPPPPPPPPPPPPPC", "CPPPPPPPPPPPPPC", "CPPPPPPPPPPPPPC", "CCCCCCCCCCCCCCC")
                .aisle("FFFFFFFFFFFFFFF", "CPPPPPPPPPPPPPC", "CPPPPPPPPPPPPPC", "CPPPPPPPPPPPPPC", "CPPPPPPPPPPPPPC", "CPPPPPPPPPPPPPC", "CPPPPPPPPPPPPPC", "CPPPPPPPPPPPPPC", "CPPPPPPPPPPPPPC", "CPPPPPPPPPPPPPC", "CPPPPPPPPPPPPPC", "CPPPPPPPPPPPPPC", "CPPPPPPPPPPPPPC", "CPPPPPPPPPPPPPC", "CPPPPPPPPPPPPPC", "CPPPPPPPPPPPPPC", "CPPPPPPPPPPPPPC", "CPPPPPPPPPPPPPC", "CPPPPPPPPPPPPPC", "CCCCCCCCCCCCCCC")
                .aisle("FFFFFFFFFFFFFFF", "CPPPPPPPPPPPPPC", "CPPPPPPPPPPPPPC", "CPPPPPPPPPPPPPC", "CPPPPPPPPPPPPPC", "CPPPPPPPPPPPPPC", "CPPPPPPPPPPPPPC", "CPPPPPPPPPPPPPC", "CPPPPPPPPPPPPPC", "CPPPPPPPPPPPPPC", "CPPPPPPPPPPPPPC", "CPPPPPPPPPPPPPC", "CPPPPPPPPPPPPPC", "CPPPPPPPPPPPPPC", "CPPPPPPPPPPPPPC", "CPPPPPPPPPPPPPC", "CPPPPPPPPPPPPPC", "CPPPPPPPPPPPPPC", "CPPPPPPPPPPPPPC", "CCCCCCCCCCCCCCC")
                .aisle("FFFFFFFFFFFFFFF", "CPPPPPPPPPPPPPC", "CPPPPPPPPPPPPPC", "CPPPPPPPPPPPPPC", "CPPPPPPPPPPPPPC", "CPPPPPPPPPPPPPC", "CPPPPPPPPPPPPPC", "CPPPPPPPPPPPPPC", "CPPPPPPPPPPPPPC", "CPPPPPPPPPPPPPC", "CPPPPPPPPPPPPPC", "CPPPPPPPPPPPPPC", "CPPPPPPPPPPPPPC", "CPPPPPPPPPPPPPC", "CPPPPPPPPPPPPPC", "CPPPPPPPPPPPPPC", "CPPPPPPPPPPPPPC", "CPPPPPPPPPPPPPC", "CPPPPPPPPPPPPPC", "CCCCCCCCCCCCCCC")
                .aisle("FFFFFFFFFFFFFFF", "CPPPPPPPPPPPPPC", "CPPPPPPPPPPPPPC", "CPPPPPPPPPPPPPC", "CPPPPPPPPPPPPPC", "CPPPPPPPPPPPPPC", "CPPPPPPPPPPPPPC", "CPPPPPPPPPPPPPC", "CPPPPPPPPPPPPPC", "CPPPPPPPPPPPPPC", "CPPPPPPPPPPPPPC", "CPPPPPPPPPPPPPC", "CPPPPPPPPPPPPPC", "CPPPPPPPPPPPPPC", "CPPPPPPPPPPPPPC", "CPPPPPPPPPPPPPC", "CPPPPPPPPPPPPPC", "CPPPPPPPPPPPPPC", "CPPPPPPPPPPPPPC", "CCCCCCCCCCCCCCC")
                .aisle("FFFFFFFFFFFFFFF", "CCCCCCCCCCCCCCC", "CCCCCCCSCCCCCCC", "CCCCCCCCCCCCCCC", "CCCCCCCCCCCCCCC", "CCCCCCCCCCCCCCC", "CCCCCCCCCCCCCCC", "CCCCCCCCCCCCCCC", "CCCCCCCCCCCCCCC", "CCCCCCCCCCCCCCC", "CCCCCCCCCCCCCCC", "CCCCCCCCCCCCCCC", "CCCCCCCCCCCCCCC", "CCCCCCCCCCCCCCC", "CCCCCCCCCCCCCCC", "CCCCCCCCCCCCCCC", "CCCCCCCCCCCCCCC", "CCCCCCCCCCCCCCC", "CCCCCCCCCCCCCCC", "CCCCCCCCCCCCCCC")
                .where('S', this.selfPredicate())
                .where('C', states(this.boilerType.casingState).setMinGlobalLimited(200)
                        .or(abilities(MultiblockAbility.EXPORT_FLUIDS)))
                .where('F', states(this.boilerType.fireboxState).setMinGlobalLimited(200)
                        .or(abilities(MultiblockAbility.IMPORT_ITEMS, MultiblockAbility.IMPORT_FLUIDS, MultiblockAbility.MAINTENANCE_HATCH,
                                MultiblockAbility.EXPORT_ITEMS))
                        .or(abilities(MultiblockAbility.MUFFLER_HATCH).setExactLimit(1)))
                .where('P', states(this.boilerType.pipeState))
                .build();
    }

    @Override
    @SideOnly(Side.CLIENT)
    public ICubeRenderer getBaseTexture(IMultiblockPart iMultiblockPart) {
        return this.boilerType.casingRenderer;
    }
}
